scripts/test_case3.txt
40
0 o
1 o
2 o
3 o
4 o
5 o
6 o
7 o
8 o
9 o
10 o
11 o
12 o
13 o
14 o
15 o
16 o
17 o
18 o
19 o
20 o
21 o
22 o
23 o
24 o
25 o
26 o
27 o
28 o
29 o
30 o
31 o
32 o
33 o
34 o
35 o
36 o
37 o
38 o
39 o
.
39 S 28865469 AMZN 49781 6300
38 S 1495990 GOOG 12248 8476
39 B 19821710 AMZN 22480 8780
38 B 75962382 GOOG 90974 6763
39 B 49216390 GOOG 96633 8127
35 S 56370410 GOOG 33728 9967
37 B 94847047 MSFT 90448 4170
38 S 40935022 MSFT 47352 4986
39 B 2533752 AMZN 56877 1253
39 S 73638717 AAPL 20963 6735
37 B 46009127 AAPL 68376 1577
39 S 84771653 AAPL 45115 5594
39 C 28865469
33 B 10158228 GOOG 22894 6008
39 B 4856591 AMZN 85157 1789
39 C 4856591
39 S 38860319 AAPL 5476 6269
38 B 97346752 AMZN 31368 9721
38 C 75962382
38 B 32158928 AAPL 17437 7689
39 S 92765312 MSFT 21810 881
39 B 87426803 AMZN 22700 1878
39 B 37043761 AAPL 52502 2547
39 B 99971298 AAPL 1942 8689
37 S 62430805 GOOG 92651 8602
36 S 30772620 AMZN 55910 1005
38 S 49702794 GOOG 20561 50
36 B 7762948 AAPL 25896 4894
39 C 84771653
39 S 85507242 AMZN 72508 585
39 B 96185695 AAPL 67367 7747
39 S 9681740 MSFT 9178 5166
39 S 99508211 GOOG 47531 9090
39 C 87426803
38 C 75962382
39 B 56722768 AMZN 17948 3283
39 B 86439831 AAPL 24951 3440
37 B 85945533 GOOG 34720 1078
38 B 17906902 AMZN 42055 1365
39 S 35703342 MSFT 2696 860
38 C 49702794
39 S 81938431 AAPL 15704 3868
38 C 17906902
37 B 22537835 AAPL 18939 8120
37 B 37068378 AMZN 93038 8613
39 B 43491730 GOOG 10799 879
38 C 1495990
38 C 32158928
39 B 68259053 GOOG 17658 2286
39 C 28865469
38 B 55264617 GOOG 89467 9188
38 B 19503995 MSFT 37524 1079
38 C 75962382
32 B 88071615 AMZN 22273 967
39 S 94298538 MSFT 42204 3840
39 S 66397566 GOOG 53672 6699
38 S 81230907 GOOG 11057 753
36 C 7762948
37 S 79745625 AAPL 60066 6614
39 B 62184553 AAPL 22187 5114
39 B 18661001 MSFT 47344 2812
39 B 26030099 AMZN 6351 1871
39 S 18919733 MSFT 16663 3736
38 B 41168748 AAPL 44011 1640
39 B 78292461 MSFT 31895 6002
39 B 32772355 AAPL 2137 4193
37 C 94847047
33 C 10158228
39 S 53974203 AMZN 55337 3160
37 S 90538328 AAPL 81394 6187
36 S 95724931 GOOG 9310 7623
39 B 60147141 GOOG 27104 7545
37 B 31664794 GOOG 13186 4530
39 S 48697129 AAPL 16436 1461
39 C 48697129
38 C 1495990
39 S 64956488 GOOG 87169 8003
39 B 42903068 AMZN 11325 5258
37 S 2459432 MSFT 15320 7837
39 B 30267776 AAPL 9057 3021
37 B 36190338 MSFT 90243 2632
39 S 22553835 AAPL 92895 9497
39 B 54886548 AAPL 39993 6747
38 S 6307029 MSFT 24767 952
39 C 37043761
39 S 56456795 GOOG 13431 3805
39 S 40209326 MSFT 54531 6323
39 B 51912357 GOOG 64071 5432
39 S 34940948 GOOG 13055 9945
39 S 24140054 GOOG 16760 19
39 S 62730323 MSFT 47946 4461
39 S 79235722 MSFT 38888 883
38 S 89575533 MSFT 35203 2403
39 B 13115395 AAPL 21900 3547
39 B 69063787 MSFT 88667 7199
39 S 36754618 GOOG 26220 7994
37 S 45060408 AAPL 28699 7623
39 C 38860319
39 S 3251679 AMZN 87082 10000
36 B 55197911 AAPL 13297 1315
38 B 6791506 AAPL 18815 9321
37 B 60264001 AAPL 6330 9421
39 S 19038982 AMZN 48799 5142
39 C 18919733
39 C 87426803
39 S 27436019 AMZN 68350 8474
39 B 83080989 AMZN 66556 3614
38 S 26442158 GOOG 86145 6048
39 B 66857270 AMZN 37996 8718
37 S 60666353 AAPL 91798 3941
36 S 42361002 AMZN 25061 3499
39 C 35703342
38 C 89575533
35 C 56370410
39 C 9681740
38 B 39504716 AMZN 43558 1647
39 B 92712137 GOOG 21008 8856
36 S 88243990 GOOG 72745 2608
38 C 49702794
36 S 59819475 AMZN 5234 8748
39 S 24731071 MSFT 48082 8949
37 S 31933641 AAPL 70092 9106
39 C 66397566
38 S 93500406 GOOG 96366 3962
39 S 64646419 AMZN 37683 7648
38 C 89575533
38 C 19503995
37 S 25452804 AMZN 94301 6747
39 S 20455341 GOOG 29236 727
39 C 19821710
37 C 46009127
39 S 21653745 AMZN 22862 8612
37 S 8409142 AAPL 28193 8408
37 C 79745625
38 S 58248399 AAPL 96774 8181
39 C 68259053
38 S 64148996 AAPL 44904 7507
38 B 52786927 AMZN 6419 5295
38 S 34230148 AMZN 92629 9748
38 B 21873468 AAPL 73729 5415
38 S 24815512 MSFT 78148 8363
38 C 39504716
39 S 23953191 AMZN 82075 3663
37 C 85945533
37 B 87971146 MSFT 39781 9235
34 S 28501931 AAPL 19706 4355
37 B 45430733 AAPL 8771 166
39 S 4318615 GOOG 49329 8644
39 C 28865469
39 S 81478208 AMZN 28603 7206
39 S 65698818 GOOG 76336 2271
38 C 32158928
39 S 67354471 GOOG 4911 6852
39 C 69063787
39 C 51912357
39 C 99971298
38 S 98563164 AMZN 36435 4328
37 B 5667885 AAPL 95521 8784
37 S 68359365 MSFT 97136 9160
37 C 87971146
38 C 58248399
38 S 68840126 GOOG 70823 9912
38 S 43788232 AAPL 84406 3077
38 C 98563164
34 C 28501931
39 B 84430681 GOOG 85234 2456
38 C 49702794
37 S 97863852 GOOG 92704 405
38 S 23440694 MSFT 67670 1543
39 S 39367888 AAPL 28930 2781
39 S 46994130 AAPL 38050 3217
39 B 61260903 AMZN 81841 6174
38 B 86964244 AMZN 97760 5834
39 S 11811660 AAPL 65978 6011
39 C 32772355
39 B 13348234 AAPL 78976 8264
36 C 42361002
34 B 72179259 AMZN 52892 4231
38 S 93030713 MSFT 91083 6084
39 S 17105538 AAPL 83391 5795
39 B 44222807 AAPL 25844 4833
38 B 66701881 GOOG 92731 1915
38 S 57483533 AMZN 45271 8598
38 B 81726227 MSFT 63837 3587
38 B 6719585 AAPL 78473 7814
39 C 46994130
37 S 49148582 MSFT 32481 8645
38 S 38173529 AMZN 75344 3531
39 B 75891623 AAPL 57539 9512
30 S 6843666 AAPL 29670 5937
39 C 64646419
39 S 35318517 AAPL 72481 151
39 B 91669727 MSFT 20259 2464
39 C 79235722
39 S 67070941 GOOG 78314 9430
39 C 56456795
38 C 57483533
35 B 6797570 AMZN 86915 5741
39 B 14122596 AMZN 17761 6577
38 B 11412967 GOOG 75086 4976
37 S 48787094 GOOG 44079 5013
37 S 8807538 AAPL 82906 4073
38 C 41168748
37 B 36084068 MSFT 16977 1520
37 S 30736792 AMZN 34203 2970
36 C 95724931
38 B 14995825 AAPL 16385 449
37 B 31142546 AAPL 84414 5227
38 S 99224914 GOOG 91464 3060
37 S 29495722 MSFT 89470 5866
38 S 63092695 GOOG 18616 7929
38 B 61327833 AMZN 93014 1284
37 C 94847047
38 S 31809777 AMZN 82310 1883
37 S 79583261 MSFT 57100 2277
37 B 97909492 GOOG 30251 5997
36 B 96082379 GOOG 85327 9381
38 B 59249762 AAPL 66152 7100
38 S 52084101 AMZN 92157 5709
38 S 81823498 AAPL 52212 6913
38 C 98563164
34 S 76827057 MSFT 18338 8011
38 C 81726227
38 S 55264130 AMZN 3135 5442
37 S 13521059 MSFT 77981 3431
34 C 76827057
38 B 37943079 GOOG 12844 9410
38 B 71407184 MSFT 87905 4779
37 C 68359365
30 C 6843666
38 S 52589227 MSFT 33315 8370
37 B 63959508 AMZN 94775 3863
38 C 11412967
35 C 6797570
38 S 390690 GOOG 59978 5294
38 S 20588328 AAPL 42789 3438
38 S 48969938 AMZN 70375 1273
38 B 25418812 MSFT 43332 6408
34 C 28501931
38 B 44457973 GOOG 15617 9933
38 B 83210718 AMZN 39370 7667
37 C 30736792
33 C 10158228
38 C 86964244
36 C 96082379
36 S 28253392 AAPL 38397 900
38 C 83210718
38 S 21962639 GOOG 44045 7472
38 B 44209900 AMZN 75984 3928
38 B 24821241 AMZN 35404 1263
37 S 59840221 MSFT 82714 3763
38 S 82235998 AMZN 82220 4739
38 C 32158928
38 B 71363143 MSFT 25855 140
36 B 33081711 AAPL 53539 6571
37 C 60264001
38 S 78882101 AAPL 68526 3549
38 C 6719585
36 S 58569273 AMZN 64147 7607
38 S 4553481 AAPL 77066 9429
37 S 348595 MSFT 36310 4816
36 S 67327958 AMZN 67262 650
37 B 36086229 MSFT 17662 7782
37 B 16481291 AAPL 45851 7135
38 C 64148996
35 C 56370410
37 S 23904916 GOOG 62526 8130
36 B 60865298 AMZN 55611 5646
37 S 83719785 AMZN 56271 3050
37 C 30736792
35 C 6797570
37 S 99748094 MSFT 75452 5717
38 S 39992205 GOOG 83136 8737
35 S 53808724 AAPL 8935 5793
37 C 36086229
38 S 16001207 GOOG 86690 1025
36 S 33637152 AAPL 59082 4205
38 S 79977425 AMZN 50754 8168
38 C 37943079
38 B 78224398 AAPL 58228 6092
37 B 87031208 AAPL 10108 48
38 B 57376517 MSFT 77401 5620
37 S 8841179 AAPL 18678 4263
38 C 16001207
38 C 83210718
38 B 44432611 MSFT 18234 3232
36 S 95248298 AAPL 5937 7435
35 C 56370410
35 C 53808724
37 B 74755943 MSFT 26832 8615
38 B 62202082 GOOG 12861 1523
35 B 20199667 GOOG 63511 1632
38 B 7485006 AMZN 45462 6733
37 S 69911321 MSFT 76002 3708
38 C 16001207
36 C 58569273
38 C 78882101
37 S 18771158 GOOG 36094 8702
37 S 80306574 GOOG 27738 8891
34 S 27772570 GOOG 47118 4950
36 C 7762948
36 B 75728459 GOOG 90650 1737
37 S 59773107 AMZN 14295 5595
37 C 31142546
37 C 97863852
37 B 87865415 MSFT 95184 4370
34 S 12643269 AAPL 38938 1753
37 C 5667885
35 C 6797570
37 B 19792110 AMZN 87110 8281
36 S 44999079 AAPL 75887 497
