scripts/test_case4.txt
40
0 o
1 o
2 o
3 o
4 o
5 o
6 o
7 o
8 o
9 o
10 o
11 o
12 o
13 o
14 o
15 o
16 o
17 o
18 o
19 o
20 o
21 o
22 o
23 o
24 o
25 o
26 o
27 o
28 o
29 o
30 o
31 o
32 o
33 o
34 o
35 o
36 o
37 o
38 o
39 o
.
38 B 78329125 AMZN 8325 7764
39 B 36716837 AMZN 41288 7057
39 C 36716837
38 S 93037576 MSFT 33982 5709
32 S 42244326 AAPL 77425 676
39 S 91013961 AMZN 67332 734
38 C 78329125
39 S 71464481 AAPL 69138 2525
37 B 45456808 GOOG 91400 9683
35 S 7152414 AAPL 56622 6585
39 S 77033199 MSFT 40912 5674
37 C 45456808
39 B 20505685 GOOG 35026 4471
39 S 20492833 AAPL 98769 5458
39 C 91013961
38 B 17498160 AMZN 20472 8302
39 C 71464481
39 S 38895899 GOOG 31783 7663
38 S 77987107 MSFT 53655 4211
39 B 36315294 MSFT 8972 9266
39 B 19908834 MSFT 25740 5297
39 S 2048693 MSFT 81989 2705
38 S 7397084 AMZN 15109 1731
38 B 16406996 MSFT 94039 1903
37 S 92818355 AAPL 32349 3879
39 S 6212143 GOOG 89621 9911
34 B 51295374 MSFT 9849 397
39 S 67807627 AAPL 18324 5689
39 B 47194483 MSFT 35889 8610
39 C 38895899
36 S 41349885 AMZN 34842 8051
37 S 79361385 AAPL 96707 4538
39 B 6817814 MSFT 83693 9676
34 C 51295374
39 B 42830640 GOOG 93982 6715
35 S 10132774 GOOG 1504 7694
39 C 38895899
37 S 71836848 MSFT 12001 4654
38 C 7397084
39 B 81663102 MSFT 2414 9803
34 B 71544892 GOOG 91449 3149
39 B 12858078 AAPL 52273 1495
39 S 49201146 AMZN 36889 3497
38 B 4142049 AAPL 25917 6716
37 S 7646622 AAPL 56807 188
39 B 58924950 AMZN 42588 4363
39 C 6212143
38 C 93037576
37 C 45456808
38 C 7397084
38 S 14848428 AAPL 94949 5164
39 S 55713526 AAPL 41806 3051
39 S 50856744 AMZN 36843 7700
36 B 69209226 GOOG 76070 9813
38 S 3892213 AMZN 33960 6533
37 S 32732357 AMZN 61761 6387
39 S 28119433 GOOG 57012 3730
35 C 7152414
37 C 32732357
39 C 20505685
36 C 69209226
39 C 36315294
38 B 13241826 AMZN 69539 6991
36 S 14261474 AAPL 68761 4262
39 C 67807627
38 C 17498160
39 S 20432172 AAPL 48912 1221
38 B 84575288 AMZN 3609 2669
38 S 25661888 GOOG 98437 6581
39 S 58783004 GOOG 68354 5035
39 C 28119433
39 B 28877569 AMZN 91965 8206
39 S 31987121 MSFT 65380 2145
37 S 20597252 GOOG 60835 171
36 B 74810150 MSFT 5526 4224
36 C 41349885
39 B 28271145 GOOG 49190 9323
38 C 25661888
38 S 62912967 AMZN 50288 8125
39 S 96648068 AAPL 67302 5108
37 B 44204057 MSFT 47335 8145
39 B 33430242 AMZN 65824 7615
39 B 40158423 AMZN 17784 5809
39 C 91013961
39 S 34095879 AMZN 60553 3931
37 B 46270218 MSFT 47568 4802
38 S 96108972 AMZN 50723 823
39 B 84515055 GOOG 17197 662
36 C 41349885
39 C 31987121
38 C 16406996
39 C 91013961
36 B 64970190 MSFT 47908 5588
39 S 51251897 GOOG 50464 9692
38 B 85657125 GOOG 17180 2032
39 B 98215098 MSFT 52838 5528
39 C 58924950
39 C 36315294
39 S 91931787 GOOG 71512 3442
34 B 20000959 MSFT 58874 9816
38 S 90171290 GOOG 21512 8290
39 B 50607643 AAPL 80273 1866
39 B 26643790 MSFT 94408 4613
38 S 88436976 AAPL 49291 7299
33 S 39874863 AAPL 18761 6059
39 S 39310936 MSFT 12416 7597
39 C 49201146
38 C 14848428
36 B 84617761 AMZN 78833 3972
38 S 93555703 AAPL 45263 3071
39 B 87757106 MSFT 37571 1195
35 B 97500961 MSFT 48695 1922
36 C 74810150
39 C 51251897
38 C 93555703
38 B 44934301 AAPL 52873 7008
39 S 4894931 MSFT 20980 4949
39 S 7376575 MSFT 86252 5368
39 C 20505685
38 S 34289522 AMZN 5404 2891
38 B 27397975 AAPL 1086 2702
39 B 28576311 MSFT 42474 9150
38 C 3892213
34 S 86898102 GOOG 39715 5317
38 B 39783812 AAPL 68562 5819
39 B 8242587 MSFT 11422 4139
36 B 52785703 AAPL 92541 2938
35 C 7152414
37 S 25260134 MSFT 81801 8312
39 C 6212143
35 S 9311810 MSFT 5512 1940
39 B 64914368 GOOG 74433 9368
37 C 25260134
36 B 44636638 AAPL 7420 9222
38 S 28821099 GOOG 5054 4114
39 S 52474156 AMZN 54065 1270
37 C 20597252
39 C 50856744
39 C 77033199
39 C 58783004
39 S 39699669 AMZN 63868 1640
39 B 5582606 AMZN 69157 2166
38 S 65621667 AAPL 30000 6907
39 B 35779361 MSFT 15023 358
39 C 81663102
36 B 2224516 AAPL 73728 225
38 S 35513915 AMZN 82341 663
39 C 67807627
39 S 41148664 GOOG 97585 5806
39 S 49465196 GOOG 7601 4656
37 S 80315919 AMZN 5643 7390
39 C 28271145
36 S 40145737 AMZN 12376 6552
39 S 95201211 GOOG 81416 9494
39 B 33909532 AMZN 72356 1262
38 B 94531331 MSFT 70425 9727
39 B 78701891 AMZN 95518 6189
37 S 63404146 GOOG 49372 4282
38 S 25211191 MSFT 90051 8317
37 S 61670635 GOOG 14210 8603
39 B 96973283 AMZN 26316 8587
39 C 77033199
39 S 23799145 AAPL 66940 7576
37 C 20597252
39 C 39699669
39 S 602237 AAPL 12676 8159
37 B 13202894 MSFT 18955 1069
38 S 9417553 GOOG 84645 6296
39 B 62434057 AMZN 63322 3806
36 B 22974747 MSFT 5510 7592
38 B 26078602 AMZN 43835 5793
39 S 10513 AMZN 37178 5446
39 S 68151666 MSFT 78451 5563
39 C 51251897
39 B 4892088 AMZN 35747 6150
33 B 19145015 AMZN 86608 9085
37 B 11567633 GOOG 31762 21
39 B 68192155 MSFT 90318 7567
39 B 68968749 GOOG 98096 4907
37 C 46270218
38 C 9417553
35 B 21443496 GOOG 64928 5020
34 B 83452875 MSFT 88131 5396
36 S 32620315 AAPL 74455 1086
38 B 48205506 AAPL 27034 2842
39 S 34518763 MSFT 24284 6795
38 C 44934301
38 C 17498160
39 S 81886543 MSFT 17510 3483
38 B 91526712 AMZN 10136 1900
39 S 54170608 AAPL 90822 3385
38 B 30293186 GOOG 83855 7159
38 S 11519713 MSFT 95625 5764
38 B 25987977 GOOG 35816 9812
36 S 77171545 AAPL 72727 9942
38 S 83161519 AAPL 53803 6903
37 S 16275055 AAPL 1617 2237
36 C 52785703
38 C 96108972
39 B 70088208 AAPL 35416 2001
38 C 65621667
39 S 10306383 AAPL 93499 8109
38 B 43192120 AMZN 22521 9645
39 S 15265115 MSFT 98675 532
36 S 47438800 AAPL 81333 9381
37 B 13150405 MSFT 18039 948
38 S 23934500 AMZN 62267 4270
37 S 3291984 GOOG 8407 6873
38 B 67087903 GOOG 36342 3705
38 C 78329125
38 S 27982506 AAPL 26220 5424
37 C 45456808
38 S 11683942 AAPL 20638 8542
38 S 55511665 AMZN 25010 7627
37 S 39118762 AAPL 93062 7021
38 B 66595559 GOOG 85998 2491
36 C 32620315
35 C 10132774
38 C 48205506
37 B 25127581 AAPL 59788 6186
38 S 23885175 MSFT 98949 9590
38 B 65206484 AMZN 55012 1891
36 B 49178178 AMZN 67333 8828
38 C 26078602
35 S 60105176 AAPL 22904 2510
38 S 72367289 GOOG 8009 8338
34 S 83994141 GOOG 30359 1849
38 S 23242632 AMZN 18142 5416
36 C 84617761
38 S 27323216 GOOG 79386 4131
38 C 43192120
38 B 22874624 AAPL 65810 511
35 S 76424339 AMZN 35149 517
38 S 19545143 AAPL 45460 1216
35 B 72464570 MSFT 17113 7654
35 C 72464570
36 C 69209226
35 C 76424339
38 C 43192120
38 B 4890020 GOOG 24337 1445
38 B 47625286 AAPL 85062 4555
38 B 58035293 MSFT 51187 7615
38 S 42484072 GOOG 5017 3927
38 S 88582248 AMZN 45224 7558
37 B 3886081 AAPL 80504 4067
37 B 65874282 MSFT 38986 2665
38 S 63844422 AMZN 85712 8687
37 B 47019698 AMZN 39671 5029
38 C 72367289
38 B 81181466 MSFT 77043 6259
35 S 52862062 AAPL 30657 2325
36 B 86098313 GOOG 48453 7950
36 B 12839482 AMZN 12680 8344
37 C 3291984
38 C 88436976
38 B 90384786 MSFT 77672 8298
38 B 48494683 MSFT 60211 6029
38 S 64648336 AMZN 88381 6766
34 C 86898102
37 S 76861036 GOOG 41552 2471
38 B 70009652 GOOG 31473 370
35 B 42990014 GOOG 94952 2720
37 C 46270218
38 B 38623379 MSFT 41409 198
36 C 41349885
36 S 90237330 MSFT 13740 6253
36 B 64831346 AMZN 79255 923
38 B 79750597 AAPL 17366 8859
37 B 36896929 MSFT 87366 4490
37 B 92918123 AMZN 87936 9960
38 C 84575288
38 B 68730293 MSFT 64995 6833
38 S 56689608 GOOG 69966 1529
38 C 78329125
36 C 52785703
38 S 23246348 MSFT 27315 7296
38 S 65385876 AMZN 67342 2817
38 B 80326070 MSFT 54059 3321
38 B 27179657 MSFT 20767 6870
37 B 79221938 MSFT 4381 9356
38 C 23242632
36 C 40145737
38 C 93555703
37 B 13625921 GOOG 30173 3490
38 S 24423237 MSFT 76394 8729
35 S 76435084 AMZN 70351 2266
38 C 16406996
38 S 67057234 GOOG 7791 3678
37 S 13159031 AMZN 64628 6515
38 B 56773690 AMZN 75287 4665
33 C 19145015
32 C 42244326
38 C 23885175
31 S 8416656 AMZN 11279 4672
34 B 18494249 GOOG 20610 9703
35 C 97500961
37 S 41481607 AMZN 51295 4454
37 C 92918123
37 B 57267314 MSFT 78372 5956
33 B 98087069 GOOG 59565 9764
37 B 99458796 AMZN 30731 4385
35 B 65961071 MSFT 79117 7144
37 C 13202894
36 C 86098313
37 B 75725855 AMZN 37323 9907
37 C 92918123
37 C 46270218
37 C 3886081
35 S 18502483 AMZN 25081 3056
36 C 64970190
37 S 53728707 AAPL 48197 8902
37 C 36896929
36 B 61126772 GOOG 1378 4659
35 B 36292703 AAPL 67802 9889
